<?xml version="1.0" ?>
<sdf version="1.8">

    <model name='alphabot2' canonical_link='telo'>
        <!-- https://gazebosim.org/api/sim/9/auto_inertia_calculation.html -->

        <!-- celkova hmotnost: 310g = 0.31kg -->
        <!-- hmotnost kolesa: 20g -->
        <!-- hmotnost bez kolies: 270g = 0.27kg -->
        <!-- objem tela: pi * 0.055^2 * 0.04 = 0.000380132711084365 -->
        <!-- hustota: 0.27 / 0.00038... = 710.278 -->
        <link name='telo'>
            <pose relative_to='__model__'>0 0 0.05 0 0 0</pose>
            <inertial auto="true" />
            <collision name='collision'>
                <density>710.278</density>
                <geometry>
                    <cylinder>
                        <radius>0.055</radius>
                        <length>0.04</length>
                    </cylinder>
                </geometry>
            </collision>
            <visual name='visual'>
                <geometry>
                    <cylinder>
                        <radius>0.055</radius>
                        <length>0.04</length>
                    </cylinder>
                </geometry>
                <material>
                    <ambient>0.0 0.0 1.0 1</ambient>
                    <diffuse>0.0 0.0 1.0 1</diffuse>
                    <specular>0.0 0.0 1.0 1</specular>
                </material>
            </visual>
        </link>


        <!-- hmotnost kolesa: 20g -->
        <!-- objem kolesa: pi * 0.022^2 * 0.017 = 0.00002584 -->
        <!-- hustota: 0.020 / 0.0000258... = 773.72359 -->
        <link name='lave_koleso'>
            <pose relative_to="telo">0 0.050 -0.011 -1.5707 0 0</pose>
            <inertial auto="true" />
            <collision name='collision'>
                <density>773.72359</density>
                <geometry>
                    <cylinder>
                        <radius>0.022</radius>
                        <length>0.017</length>
                    </cylinder>
                </geometry>
            </collision>
            <visual name='visual'>
                <geometry>
                    <cylinder>
                        <radius>0.022</radius>
                        <length>0.017</length>
                    </cylinder>
                </geometry>
                <material>
                    <ambient>1.0 0.0 0.0 1</ambient>
                    <diffuse>1.0 0.0 0.0 1</diffuse>
                    <specular>1.0 0.0 0.0 1</specular>
                </material>
            </visual>
        </link>
        <joint name='lave_koleso_zaves' type='revolute'>
            <pose relative_to='lave_koleso'/>
            <parent>telo</parent>
            <child>lave_koleso</child>
            <axis>
                <xyz expressed_in='__model__'>0 1 0</xyz> <!--can be descired to any frame or even arbitrary frames-->
                <limit>
                    <lower>-1.79769e+308</lower>    <!--negative infinity-->
                    <upper>1.79769e+308</upper>     <!--positive infinity-->
                </limit>
            </axis>
        </joint>


        <link name='prave_koleso'>
            <pose relative_to="telo">0 -0.050 -0.011 -1.5707 0 0</pose>
            <inertial auto="true" />
            <collision name='collision'>
                <density>773.72359</density>
                <geometry>
                    <cylinder>
                        <radius>0.022</radius>
                        <length>0.017</length>
                    </cylinder>
                </geometry>
            </collision>
            <visual name='visual'>
                <geometry>
                    <cylinder>
                        <radius>0.022</radius>
                        <length>0.017</length>
                    </cylinder>
                </geometry>
                <material>
                    <ambient>1.0 0.0 0.0 1</ambient>
                    <diffuse>1.0 0.0 0.0 1</diffuse>
                    <specular>1.0 0.0 0.0 1</specular>
                </material>
            </visual>
        </link>
        <joint name='prave_koleso_zaves' type='revolute'>
            <pose relative_to='prave_koleso'/>
            <parent>telo</parent>
            <child>prave_koleso</child>
            <axis>
                <xyz expressed_in='__model__'>0 1 0</xyz>
                <limit>
                    <lower>-1.79769e+308</lower>    <!--negative infinity-->
                    <upper>1.79769e+308</upper>     <!--positive infinity-->
                </limit>
            </axis>
        </joint>


        <!-- radius: 1.2 cm -->
        <link name='caster1'>
            <pose relative_to="telo">-0.050 0 -0.025 -1.5707 0 0</pose>
            <inertial auto="true" />
            <collision name='collision'>
                <density>1000</density>
                <geometry>
                    <sphere>
                        <radius>0.006</radius>
                    </sphere>
                </geometry>
            </collision>
            <visual name='visual'>
                <geometry>
                    <sphere>
                        <radius>0.006</radius>
                    </sphere>
                </geometry>
                <material>
                    <ambient>0.0 1 0.0 1</ambient>
                    <diffuse>0.0 1 0.0 1</diffuse>
                    <specular>0.0 1 0.0 1</specular>
                </material>
            </visual>
        </link>
        <joint name='caster1_zaves' type='fixed'>
            <parent>telo</parent>
            <child>caster1</child>
        </joint>

        <link name='caster2'>
            <pose relative_to="telo">0.050 0 -0.025 -1.5707 0 0</pose>
            <inertial auto="true" />
            <collision name='collision'>
                <density>1000</density>
                <geometry>
                    <sphere>
                        <radius>0.006</radius>
                    </sphere>
                </geometry>
            </collision>
            <visual name='visual'>
                <geometry>
                    <sphere>
                        <radius>0.006</radius>
                    </sphere>
                </geometry>
                <material>
                    <ambient>0.0 1 0.0 1</ambient>
                    <diffuse>0.0 1 0.0 1</diffuse>
                    <specular>0.0 1 0.0 1</specular>
                </material>
            </visual>
        </link>
        <joint name='caster2_zaves' type='fixed'>
            <parent>telo</parent>
            <child>caster2</child>
        </joint>


        <ros2_control name="RealRobot" type="system">
            <hardware>
                <plugin>alphabot2_diffdrive/DiffDriveAlphabot2</plugin>
                <param name="lave_koleso_nazov">lave_koleso_zaves</param>
                <param name="prave_koleso_nazov">prave_koleso_zaves</param>
                <param name="max_rychlost_kolesa">10.0</param>
            </hardware>

            <joint name="lave_koleso_zaves">
                <command_interface name="velocity">
                    <param name="min">-10</param>
                    <param name="max">10</param>
                </command_interface>
                <state_interface name="position"/>
                <state_interface name="velocity"/>
            </joint>
            <joint name="prave_koleso_zaves">
                <command_interface name="velocity">
                    <param name="min">-10</param>
                    <param name="max">10</param>
                </command_interface>
                <state_interface name="position"/>
                <state_interface name="velocity"/>
            </joint>
        </ros2_control>

    </model>

</sdf>
