<?xml version="1.0" ?>
<sdf version="1.8">

    <model name='alphabot2' canonical_link='telo'>
        <!-- https://gazebosim.org/api/sim/9/auto_inertia_calculation.html -->

        <!-- celkova hmotnost: 310g = 0.31kg -->
        <!-- hmotnost kolesa: 20g -->
        <!-- hmotnost bez kolies: 270g = 0.27kg -->
        <!-- objem tela: pi * 0.055^2 * 0.04 = 0.000380132711084365 -->
        <!-- hustota: 0.27 / 0.00038... = 710.278 -->
        <link name='telo'>
            <pose relative_to='__model__'>0 0 0.031 0 0 0</pose>    <!-- __model__ -->
            <inertial auto="true" />
            <collision name='collision'>
                <density>710.278</density>
                <geometry>
                    <cylinder>
                        <radius>0.055</radius>
                        <length>0.04</length>
                    </cylinder>
                </geometry>
            </collision>
            <visual name='visual'>
                <geometry>
                    <cylinder>
                        <radius>0.055</radius>
                        <length>0.04</length>
                    </cylinder>
                </geometry>
                <material>
                    <ambient>0.0 0.0 1.0 1</ambient>
                    <diffuse>0.0 0.0 1.0 1</diffuse>
                    <specular>0.0 0.0 1.0 1</specular>
                </material>
            </visual>
        </link>

        <!-- hmotnost kolesa: 20g -->
        <!-- objem kolesa: pi * 0.022^2 * 0.017 = 0.00002584 -->
        <!-- hustota: 0.020 / 0.0000258... = 773.72359 -->
        <link name='lave_koleso'>
            <pose relative_to="telo">0 0.050 -0.009 -1.5707 0 0</pose>
            <inertial auto="true" />
            <collision name='collision'>
                <density>773.72359</density>
                <geometry>
                    <cylinder>
                        <radius>0.022</radius>
                        <length>0.017</length>
                    </cylinder>
                </geometry>
            </collision>
            <visual name='visual'>
                <geometry>
                    <cylinder>
                        <radius>0.022</radius>
                        <length>0.017</length>
                    </cylinder>
                </geometry>
                <material>
                    <ambient>1.0 0.0 0.0 1</ambient>
                    <diffuse>1.0 0.0 0.0 1</diffuse>
                    <specular>1.0 0.0 0.0 1</specular>
                </material>
            </visual>
        </link>
        <joint name='lave_koleso_zaves' type='revolute'>
            <pose relative_to='lave_koleso'/>
            <parent>telo</parent>
            <child>lave_koleso</child>
            <axis>
                <xyz expressed_in='__model__'>0 1 0</xyz> <!--can be descired to any frame or even arbitrary frames-->
                <limit>
                    <lower>-1.79769e+308</lower>    <!--negative infinity-->
                    <upper>1.79769e+308</upper>     <!--positive infinity-->
                </limit>
            </axis>
        </joint>

        <link name='prave_koleso'>
            <pose relative_to="telo">0 -0.050 -0.009 -1.5707 0 0</pose>
            <inertial auto="true" />
            <collision name='collision'>
                <density>773.72359</density>
                <geometry>
                    <cylinder>
                        <radius>0.022</radius>
                        <length>0.017</length>
                    </cylinder>
                </geometry>
            </collision>
            <visual name='visual'>
                <geometry>
                    <cylinder>
                        <radius>0.022</radius>
                        <length>0.017</length>
                    </cylinder>
                </geometry>
                <material>
                    <ambient>1.0 0.0 0.0 1</ambient>
                    <diffuse>1.0 0.0 0.0 1</diffuse>
                    <specular>1.0 0.0 0.0 1</specular>
                </material>
            </visual>
        </link>
        <joint name='prave_koleso_zaves' type='revolute'>
            <pose relative_to='prave_koleso'/>
            <parent>telo</parent>
            <child>prave_koleso</child>
            <axis>
                <xyz expressed_in='__model__'>0 1 0</xyz>
                <limit>
                    <lower>-1.79769e+308</lower>    <!--negative infinity-->
                    <upper>1.79769e+308</upper>     <!--positive infinity-->
                </limit>
            </axis>
        </joint>


        <!-- radius: 1.2 cm -->
        <link name='caster1'>
            <pose relative_to="telo">-0.050 0 -0.025 -1.5707 0 0</pose>
            <inertial auto="true" />
            <collision name='collision'>
                <density>1000</density>
                <geometry>
                    <sphere>
                        <radius>0.006</radius>
                    </sphere>
                </geometry>
                <surface>
                    <friction>
                        <ode>
                          <mu>0.001</mu>
                          <mu2>0.001</mu2>
                        </ode>
                    </friction>
                </surface>
            </collision>
            <visual name='visual'>
                <geometry>
                    <sphere>
                        <radius>0.006</radius>
                    </sphere>
                </geometry>
                <material>
                    <ambient>0.0 1 0.0 1</ambient>
                    <diffuse>0.0 1 0.0 1</diffuse>
                    <specular>0.0 1 0.0 1</specular>
                </material>
            </visual>
        </link>
        <joint name='caster1_zaves' type='fixed'>
            <parent>telo</parent>
            <child>caster1</child>
        </joint>

        <link name='caster2'>
            <pose relative_to="telo">0.050 0 -0.025 -1.5707 0 0</pose>
            <inertial auto="true" />
            <collision name='collision'>
                <density>1000</density>
                <geometry>
                    <sphere>
                        <radius>0.006</radius>
                    </sphere>
                </geometry>
                <surface>
                    <friction>
                        <ode>
                          <mu>0.001</mu>
                          <mu2>0.001</mu2>
                        </ode>
                    </friction>
                </surface>
            </collision>
            <visual name='visual'>
                <geometry>
                    <sphere>
                        <radius>0.006</radius>
                    </sphere>
                </geometry>
                <material>
                    <ambient>0.0 1 0.0 1</ambient>
                    <diffuse>0.0 1 0.0 1</diffuse>
                    <specular>0.0 1 0.0 1</specular>
                </material>
            </visual>
        </link>
        <joint name='caster2_zaves' type='fixed'>
            <parent>telo</parent>
            <child>caster2</child>
        </joint>

        <!-- lidar -->
        <frame name="lidar_frame" attached_to='telo'>
            <pose>0.0 0 0.04 0 0 0</pose>
        </frame>
        <link name='lidar'>
            <pose relative_to='lidar_frame'/>
            <inertial auto="true" />
            <collision name='collision'>
                <geometry>
                    <cylinder>
                        <radius>0.027</radius>
                        <length>0.04</length>
                    </cylinder>
                </geometry>
            </collision>
            <visual name='visual'>
                <geometry>
                    <cylinder>
                        <radius>0.027</radius>
                        <length>0.04</length>
                    </cylinder>
                </geometry>
                <material>
                    <ambient>1.0 0.0 1.0 1</ambient>
                    <diffuse>1.0 0.0 1.0 1</diffuse>
                    <specular>1.0 0.0 1.0 1</specular>
                </material>
            </visual>
            <sensor name="lidar" type="gpu_lidar">
                <pose relative_to="lidar_frame">0 0 0 0 0 0</pose>
                <topic>scan</topic>
                <gz_frame_id>lidar</gz_frame_id>
                <update_rate>10</update_rate> <!-- 10 Hz = 0.1 s -->
                <always_on>1</always_on>
                <visualize>1</visualize>
                <ray>
                    <scan>
                        <horizontal>
                            <samples>640</samples>
                            <resolution>1</resolution>
                            <min_angle>-3.14</min_angle>
                            <max_angle>3.14</max_angle>
                        </horizontal>
                        <vertical>
                            <samples>1</samples>
                            <resolution>0.01</resolution>
                            <min_angle>0</min_angle>
                            <max_angle>0</max_angle>
                        </vertical>
                    </scan>
                    <range>
                        <min>0.08</min>
                        <max>10.0</max>
                        <resolution>0.01</resolution>
                    </range>
                </ray>
            </sensor>
        </link>
        <joint name='lidar_pripoj' type='fixed'>
            <parent>telo</parent>
            <child>lidar</child>
        </joint>

        <!-- Gazebo Diff Drive -->
        <plugin filename="gz-sim-diff-drive-system"
                name="gz::sim::systems::DiffDrive">
            <left_joint>lave_koleso_zaves</left_joint>
            <right_joint>prave_koleso_zaves</right_joint>
<!--            <wheel_separation>0.087</wheel_separation>-->
            <wheel_separation>0.1</wheel_separation>
            <wheel_radius>0.022</wheel_radius>
            <odom_publish_frequency>10</odom_publish_frequency>

            <max_linear_acceleration>0.1</max_linear_acceleration>

            <topic>cmd_vel</topic>
            <odom_topic>odom</odom_topic>
            <tf_topic>tf</tf_topic>

            <frame_id>odom</frame_id>
            <child_frame_id>telo</child_frame_id>
        </plugin>
        <plugin filename="gz-sim-joint-state-publisher-system"
                name="gz::sim::systems::JointStatePublisher">
            <topic>joint_states</topic> <!--from <ros><remapping> -->
            <joint_name>lave_koleso_zaves</joint_name>
            <joint_name>prave_koleso_zaves</joint_name>
        </plugin>

        <!-- pre SLAM Toolbox -->
<!--        <link name="base_footprint">-->
<!--        </link>-->
<!--        <joint name="base_footprint_pripoj" type="fixed">-->
<!--            <parent>telo</parent>-->
<!--            <child>base_footprint</child>-->
<!--        </joint>-->

    </model>

</sdf>
